<?xml version="1.0"?>
<robot xmlns:xacro="http://www.ros.org/wiki/xacro" name="my_robot">
  <xacro:property name="base_length" value="0.5"/>
  <xacro:property name="base_width" value="0.3"/>
  <xacro:property name="base_height" value="0.15"/>
  <xacro:property name="wheel_radius" value="0.08"/>
  <xacro:property name="wheel_width" value="0.05"/>
  <xacro:property name="wheel_zoff" value="0.05"/>
  <xacro:property name="caster_radius" value="0.08"/>

  <material name="blue"><color rgba="0.2 0.4 0.8 1.0"/></material>
  <material name="black"><color rgba="0.1 0.1 0.1 1.0"/></material>
  <material name="white"><color rgba="0.9 0.9 0.9 1.0"/></material>
  <material name="red"><color rgba="0.8 0.1 0.1 1.0"/></material>
  <material name="grey"><color rgba="0.5 0.5 0.5 1.0"/></material>

  <link name="base_link">
    <visual><geometry><box size="${base_length} ${base_width} ${base_height}"/></geometry><material name="blue"/></visual>
    <collision><geometry><box size="${base_length} ${base_width} ${base_height}"/></geometry></collision>
    <inertial><mass value="15.0"/><inertia ixx="0.1" ixy="0.0" ixz="0.0" iyy="0.15" iyz="0.0" izz="0.2"/></inertial>
  </link>

  <!-- 驱动轮：绕 Y 轴旋转 -->
  <xacro:macro name="wheel" params="prefix reflect">
    <link name="${prefix}_wheel">
      <visual><origin xyz="0 0 0" rpy="${pi/2} 0 0"/><geometry><cylinder radius="${wheel_radius}" length="${wheel_width}"/></geometry><material name="black"/></visual>
      <collision><origin xyz="0 0 0" rpy="${pi/2} 0 0"/><geometry><cylinder radius="${wheel_radius}" length="${wheel_width}"/></geometry></collision>
      <inertial><origin xyz="0 0 0" rpy="${pi/2} 0 0"/><mass value="1.5"/><inertia ixx="0.005" ixy="0.0" ixz="0.0" iyy="0.005" iyz="0.0" izz="0.01"/></inertial>
    </link>
    <joint name="${prefix}_wheel_joint" type="continuous">
      <parent link="base_link"/><child link="${prefix}_wheel"/>
      <origin xyz="0 ${reflect*(base_width/2+0.025)} -${wheel_zoff}" rpy="0 0 0"/>
      <axis xyz="0 1 0"/>
    </joint>
    <gazebo reference="${prefix}_wheel"><mu1>1.0</mu1><mu2>1.0</mu2><material>Gazebo/Black</material></gazebo>
  </xacro:macro>
  <xacro:wheel prefix="left" reflect="1"/>
  <xacro:wheel prefix="right" reflect="-1"/>

  <!-- 万向轮 -->
  <link name="caster_wheel">
    <visual><geometry><sphere radius="${caster_radius}"/></geometry><material name="grey"/></visual>
    <collision><geometry><sphere radius="${caster_radius}"/></geometry></collision>
    <inertial><mass value="0.5"/><inertia ixx="0.001" ixy="0.0" ixz="0.0" iyy="0.001" iyz="0.0" izz="0.001"/></inertial>
  </link>
  <joint name="caster_joint" type="fixed">
    <parent link="base_link"/><child link="caster_wheel"/>
    <origin xyz="-${base_length/3} 0 -${wheel_zoff}" rpy="0 0 0"/>
  </joint>
  <gazebo reference="caster_wheel"><mu1>0.1</mu1><mu2>0.1</mu2></gazebo>

  <!-- LiDAR -->
  <link name="laser_link">
    <visual><geometry><cylinder radius="0.03" length="0.05"/></geometry><material name="red"/></visual>
    <collision><geometry><cylinder radius="0.03" length="0.05"/></geometry></collision>
    <inertial><mass value="0.1"/><inertia ixx="0.0001" ixy="0.0" ixz="0.0" iyy="0.0001" iyz="0.0" izz="0.0001"/></inertial>
  </link>
  <joint name="laser_joint" type="fixed">
    <parent link="base_link"/><child link="laser_link"/>
    <origin xyz="${base_length/3} 0 ${base_height/2+0.05}" rpy="0 0 0"/>
  </joint>
  <gazebo reference="laser_link">
    <sensor name="laser" type="ray">
      <always_on>true</always_on><visualize>true</visualize><update_rate>20</update_rate>
      <ray><scan><horizontal><samples>360</samples><resolution>1</resolution><min_angle>-3.14159</min_angle><max_angle>3.14159</max_angle></horizontal></scan><range><min>0.12</min><max>12.0</max><resolution>0.015</resolution></range></ray>
      <plugin name="laser_plugin" filename="libgazebo_ros_ray_sensor.so">
        <ros><remapping>~/out:=scan</remapping></ros>
        <output_type>sensor_msgs/LaserScan</output_type><frame_name>laser_link</frame_name>
      </plugin>
    </sensor>
  </gazebo>

  <!-- RGB-D 相机 -->
  <link name="camera_link">
    <visual><geometry><box size="0.05 0.15 0.03"/></geometry><material name="white"/></visual>
    <collision><geometry><box size="0.05 0.15 0.03"/></geometry></collision>
    <inertial><mass value="0.2"/><inertia ixx="0.001" ixy="0.0" ixz="0.0" iyy="0.001" iyz="0.0" izz="0.001"/></inertial>
  </link>
  <joint name="camera_joint" type="fixed">
    <parent link="base_link"/><child link="camera_link"/>
    <origin xyz="${base_length/3} 0 ${base_height/2+0.15}" rpy="0 0 0"/>
  </joint>
  <gazebo reference="camera_link">
    <sensor name="depth_camera" type="depth">
      <always_on>true</always_on><visualize>true</visualize><update_rate>30</update_rate>
      <camera><horizontal_fov>1.047</horizontal_fov><image><width>320</width><height>240</height><format>R8G8B8</format></image><clip><near>0.05</near><far>10.0</far></clip></camera>
      <plugin name="depth_plugin" filename="libgazebo_ros_camera.so">
        <imageTopicName>color/image_raw</imageTopicName>
        <cameraInfoTopicName>color/camera_info</cameraInfoTopicName>
        <depthImageTopicName>depth/image_rect_raw</depthImageTopicName>
        <depthImageCameraInfoTopicName>depth/camera_info</depthImageCameraInfoTopicName>
        <pointCloudTopicName>depth/color/points</pointCloudTopicName>
        <frameName>camera_link</frameName>
        <distortionK1>0</distortionK1><distortionK2>0</distortionK2><distortionK3>0</distortionK3>
        <distortionT1>0</distortionT1><distortionT2>0</distortionT2>
      </plugin>
    </sensor>
  </gazebo>

  <!-- IMU：修复！origin 设为 0 0 0，与 base_link 完全重合 -->
  <link name="imu_link">
    <visual><geometry><box size="0.02 0.02 0.02"/></geometry><material name="grey"/></visual>
    <inertial><mass value="0.01"/><inertia ixx="0.000001" ixy="0.0" ixz="0.0" iyy="0.000001" iyz="0.0" izz="0.000001"/></inertial>
  </link>
  <joint name="imu_joint" type="fixed">
    <parent link="base_link"/><child link="imu_link"/>
    <!-- 关键修复：xyz 全为 0，确保 IMU 与 base_link 重合 -->
    <origin xyz="0 0 0" rpy="0 0 0"/>
  </joint>
  <gazebo reference="imu_link">
    <sensor name="imu_sensor" type="imu">
      <always_on>true</always_on><visualize>false</visualize><update_rate>100</update_rate>
      <imu>
        <angular_velocity><x><noise type="gaussian"><mean>0.0</mean><stddev>0.01</stddev></noise></x><y><noise type="gaussian"><mean>0.0</mean><stddev>0.01</stddev></noise></y><z><noise type="gaussian"><mean>0.0</mean><stddev>0.01</stddev></noise></z></angular_velocity>
        <linear_acceleration><x><noise type="gaussian"><mean>0.0</mean><stddev>0.05</stddev></noise></x><y><noise type="gaussian"><mean>0.0</mean><stddev>0.05</stddev></noise></y><z><noise type="gaussian"><mean>0.0</mean><stddev>0.05</stddev></noise></z></linear_acceleration>
      </imu>
      <plugin name="imu_plugin" filename="libgazebo_ros_imu_sensor.so">
        <ros><remapping>~/out:=imu/data</remapping></ros><frame_name>imu_link</frame_name>
      </plugin>
    </sensor>
  </gazebo>

  <!-- 差速驱动插件 -->
  <gazebo>
    <plugin name="diff_drive" filename="libgazebo_ros_diff_drive.so">
      <ros><namespace>/</namespace><remapping>cmd_vel:=cmd_vel</remapping><remapping>odom:=odom</remapping></ros>
      <update_rate>50</update_rate><left_joint>left_wheel_joint</left_joint><right_joint>right_wheel_joint</right_joint>
      <wheel_separation>0.4</wheel_separation><wheel_diameter>0.16</wheel_diameter>
      <max_wheel_torque>20</max_wheel_torque><max_wheel_acceleration>1.0</max_wheel_acceleration>
      <publish_odom>true</publish_odom><publish_odom_tf>true</publish_odom_tf>
      <odometry_frame>odom</odometry_frame><robot_base_frame>base_link</robot_base_frame>
    </plugin>
  </gazebo>
  <gazebo reference="base_link"><material>Gazebo/Blue</material></gazebo>
</robot>
